2025-04-25 23:32:55,127 - __main__ - INFO - Starting installation...
2025-04-25 23:32:55,127 - __main__ - INFO - Creating directories...
2025-04-25 23:32:55,128 - __main__ - INFO - Created directory: models/nlp
2025-04-25 23:32:55,129 - __main__ - INFO - Created directory: models/wake_word
2025-04-25 23:32:55,129 - __main__ - INFO - Created directory: data/voice
2025-04-25 23:32:55,130 - __main__ - INFO - Created directory: data/conversation
2025-04-25 23:32:55,130 - __main__ - INFO - Created directory: logs
2025-04-25 23:32:55,130 - __main__ - INFO - Directories created successfully
2025-04-25 23:32:55,131 - __main__ - INFO - Installing dependencies...
2025-04-25 23:32:55,131 - __main__ - INFO - Running: Installing requirements
2025-04-25 23:35:22,924 - __main__ - ERROR - Command failed: Installing requirements
2025-04-25 23:35:22,925 - __main__ - ERROR - Error: WARNING: Ignoring invalid distribution ~otebook (C:\Users\akhil\AppData\Local\Programs\Python\Python312\Lib\site-packages)
  error: subprocess-exited-with-error
  
  × Getting requirements to build wheel did not run successfully.
  │ exit code: 1
  ╰─> [33 lines of output]
      Traceback (most recent call last):
        File "C:\Users\akhil\AppData\Local\Programs\Python\Python312\Lib\site-packages\pip\_vendor\pyproject_hooks\_in_process\_in_process.py", line 389, in <module>
          main()
        File "C:\Users\akhil\AppData\Local\Programs\Python\Python312\Lib\site-packages\pip\_vendor\pyproject_hooks\_in_process\_in_process.py", line 373, in main
          json_out["return_val"] = hook(**hook_input["kwargs"])
                                   ^^^^^^^^^^^^^^^^^^^^^^^^^^^^
        File "C:\Users\akhil\AppData\Local\Programs\Python\Python312\Lib\site-packages\pip\_vendor\pyproject_hooks\_in_process\_in_process.py", line 137, in get_requires_for_build_wheel
          backend = _build_backend()
                    ^^^^^^^^^^^^^^^^
        File "C:\Users\akhil\AppData\Local\Programs\Python\Python312\Lib\site-packages\pip\_vendor\pyproject_hooks\_in_process\_in_process.py", line 70, in _build_backend
          obj = import_module(mod_path)
                ^^^^^^^^^^^^^^^^^^^^^^^
        File "C:\Users\akhil\AppData\Local\Programs\Python\Python312\Lib\importlib\__init__.py", line 90, in import_module
          return _bootstrap._gcd_import(name[level:], package, level)
                 ^^^^^^^^^^^^^^^^^^^^^^^^^^^^^^^^^^^^^^^^^^^^^^^^^^^^
        File "<frozen importlib._bootstrap>", line 1381, in _gcd_import
        File "<frozen importlib._bootstrap>", line 1354, in _find_and_load
        File "<frozen importlib._bootstrap>", line 1304, in _find_and_load_unlocked
        File "<frozen importlib._bootstrap>", line 488, in _call_with_frames_removed
        File "<frozen importlib._bootstrap>", line 1381, in _gcd_import
        File "<frozen importlib._bootstrap>", line 1354, in _find_and_load
        File "<frozen importlib._bootstrap>", line 1325, in _find_and_load_unlocked
        File "<frozen importlib._bootstrap>", line 929, in _load_unlocked
        File "<frozen importlib._bootstrap_external>", line 994, in exec_module
        File "<frozen importlib._bootstrap>", line 488, in _call_with_frames_removed
        File "C:\Users\akhil\AppData\Local\Temp\pip-build-env-1g7d3_va\overlay\Lib\site-packages\setuptools\__init__.py", line 16, in <module>
          import setuptools.version
        File "C:\Users\akhil\AppData\Local\Temp\pip-build-env-1g7d3_va\overlay\Lib\site-packages\setuptools\version.py", line 1, in <module>
          import pkg_resources
        File "C:\Users\akhil\AppData\Local\Temp\pip-build-env-1g7d3_va\overlay\Lib\site-packages\pkg_resources\__init__.py", line 2172, in <module>
          register_finder(pkgutil.ImpImporter, find_on_path)
                          ^^^^^^^^^^^^^^^^^^^
      AttributeError: module 'pkgutil' has no attribute 'ImpImporter'. Did you mean: 'zipimporter'?
      [end of output]
  
  note: This error originates from a subprocess, and is likely not a problem with pip.
error: subprocess-exited-with-error

× Getting requirements to build wheel did not run successfully.
│ exit code: 1
╰─> See above for output.

note: This error originates from a subprocess, and is likely not a problem with pip.

2025-04-25 23:35:22,930 - __main__ - ERROR - Failed to install requirements
2025-04-25 23:35:22,931 - __main__ - ERROR - Installation failed
2025-04-25 23:36:25,955 - __main__ - INFO - Starting installation...
2025-04-25 23:36:25,956 - __main__ - INFO - Creating directories...
2025-04-25 23:36:25,956 - __main__ - INFO - Created directory: models/nlp
2025-04-25 23:36:25,956 - __main__ - INFO - Created directory: models/wake_word
2025-04-25 23:36:25,956 - __main__ - INFO - Created directory: data/voice
2025-04-25 23:36:25,957 - __main__ - INFO - Created directory: data/conversation
2025-04-25 23:36:25,957 - __main__ - INFO - Created directory: logs
2025-04-25 23:36:25,957 - __main__ - INFO - Directories created successfully
2025-04-25 23:36:25,957 - __main__ - INFO - Installing dependencies...
2025-04-25 23:36:25,957 - __main__ - INFO - Checking Python version...
2025-04-25 23:36:25,958 - __main__ - WARNING - Python version 3.12 may have compatibility issues with some packages.
2025-04-25 23:36:25,958 - __main__ - WARNING - Consider using Python 3.8-3.11 for better compatibility.
2025-04-25 23:36:25,958 - __main__ - INFO - Python version 3.12 is compatible.
2025-04-25 23:36:25,958 - __main__ - INFO - Running: Upgrading pip
2025-04-25 23:36:29,062 - __main__ - ERROR - Command failed: Upgrading pip
2025-04-25 23:36:29,062 - __main__ - ERROR - Error: WARNING: Ignoring invalid distribution ~otebook (C:\Users\akhil\AppData\Local\Programs\Python\Python312\Lib\site-packages)
ERROR: Could not install packages due to an OSError: Could not find a suitable TLS CA certificate bundle, invalid path: C:\Program Files\PostgreSQL\17\ssl\certs\ca-bundle.crt


2025-04-25 23:36:29,063 - __main__ - INFO - Running: Installing setuptools and wheel
2025-04-25 23:36:31,994 - __main__ - ERROR - Command failed: Installing setuptools and wheel
2025-04-25 23:36:31,995 - __main__ - ERROR - Error: WARNING: Ignoring invalid distribution ~otebook (C:\Users\akhil\AppData\Local\Programs\Python\Python312\Lib\site-packages)
ERROR: Could not install packages due to an OSError: Could not find a suitable TLS CA certificate bundle, invalid path: C:\Program Files\PostgreSQL\17\ssl\certs\ca-bundle.crt


2025-04-25 23:36:31,997 - __main__ - INFO - Running: Installing numpy>=1.21.0
2025-04-25 23:36:38,099 - __main__ - INFO - Command completed successfully: Installing numpy>=1.21.0
2025-04-25 23:36:38,100 - __main__ - INFO - Running: Installing pandas>=2.0.0
2025-04-25 23:36:44,179 - __main__ - INFO - Command completed successfully: Installing pandas>=2.0.0
2025-04-25 23:36:44,180 - __main__ - INFO - Running: Installing scipy>=1.10.0
2025-04-25 23:36:51,584 - __main__ - INFO - Command completed successfully: Installing scipy>=1.10.0
2025-04-25 23:36:51,584 - __main__ - INFO - Running: Installing PyYAML>=6.0
2025-04-25 23:36:58,258 - __main__ - INFO - Command completed successfully: Installing PyYAML>=6.0
2025-04-25 23:36:58,259 - __main__ - INFO - Running: Installing python-dotenv>=1.0.0
2025-04-25 23:37:05,222 - __main__ - INFO - Command completed successfully: Installing python-dotenv>=1.0.0
2025-04-25 23:37:05,223 - __main__ - INFO - Running: Installing aiohttp>=3.8.0
2025-04-25 23:37:12,254 - __main__ - INFO - Command completed successfully: Installing aiohttp>=3.8.0
2025-04-25 23:37:12,255 - __main__ - INFO - Running: Installing asyncio>=3.4.3
2025-04-25 23:37:17,346 - __main__ - INFO - Command completed successfully: Installing asyncio>=3.4.3
2025-04-25 23:37:17,346 - __main__ - INFO - Running: Installing typing-extensions>=4.5.0
2025-04-25 23:37:22,456 - __main__ - INFO - Command completed successfully: Installing typing-extensions>=4.5.0
2025-04-25 23:37:22,456 - __main__ - INFO - Running: Installing sounddevice>=0.4.4
2025-04-25 23:37:27,428 - __main__ - INFO - Command completed successfully: Installing sounddevice>=0.4.4
2025-04-25 23:37:27,429 - __main__ - INFO - Running: Installing soundfile>=0.10.3
2025-04-25 23:37:32,995 - __main__ - INFO - Command completed successfully: Installing soundfile>=0.10.3
2025-04-25 23:37:32,995 - __main__ - INFO - Running: Installing pyttsx3>=2.90
2025-04-25 23:37:38,807 - __main__ - INFO - Command completed successfully: Installing pyttsx3>=2.90
2025-04-25 23:37:38,808 - __main__ - INFO - Running: Installing SpeechRecognition>=3.8.1
2025-04-25 23:37:43,805 - __main__ - INFO - Command completed successfully: Installing SpeechRecognition>=3.8.1
2025-04-25 23:37:43,806 - __main__ - INFO - Running: Installing pyaudio>=0.2.11
2025-04-25 23:37:48,963 - __main__ - INFO - Command completed successfully: Installing pyaudio>=0.2.11
2025-04-25 23:37:48,964 - __main__ - INFO - Running: Installing spaCy model
2025-04-25 23:37:55,964 - __main__ - ERROR - Command failed: Installing spaCy model
2025-04-25 23:37:55,965 - __main__ - ERROR - Error: Traceback (most recent call last):
  File "<frozen runpy>", line 198, in _run_module_as_main
  File "<frozen runpy>", line 88, in _run_code
  File "C:\Users\akhil\AppData\Local\Programs\Python\Python312\Lib\site-packages\spacy\__main__.py", line 4, in <module>
    setup_cli()
  File "C:\Users\akhil\AppData\Local\Programs\Python\Python312\Lib\site-packages\spacy\cli\_util.py", line 87, in setup_cli
    command(prog_name=COMMAND)
  File "C:\Users\akhil\AppData\Local\Programs\Python\Python312\Lib\site-packages\click\core.py", line 1161, in __call__
    return self.main(*args, **kwargs)
           ^^^^^^^^^^^^^^^^^^^^^^^^^^
  File "C:\Users\akhil\AppData\Local\Programs\Python\Python312\Lib\site-packages\typer\core.py", line 743, in main
    return _main(
           ^^^^^^
  File "C:\Users\akhil\AppData\Local\Programs\Python\Python312\Lib\site-packages\typer\core.py", line 198, in _main
    rv = self.invoke(ctx)
         ^^^^^^^^^^^^^^^^
  File "C:\Users\akhil\AppData\Local\Programs\Python\Python312\Lib\site-packages\click\core.py", line 1697, in invoke
    return _process_result(sub_ctx.command.invoke(sub_ctx))
                           ^^^^^^^^^^^^^^^^^^^^^^^^^^^^^^^
  File "C:\Users\akhil\AppData\Local\Programs\Python\Python312\Lib\site-packages\click\core.py", line 1443, in invoke
    return ctx.invoke(self.callback, **ctx.params)
           ^^^^^^^^^^^^^^^^^^^^^^^^^^^^^^^^^^^^^^^
  File "C:\Users\akhil\AppData\Local\Programs\Python\Python312\Lib\site-packages\click\core.py", line 788, in invoke
    return __callback(*args, **kwargs)
           ^^^^^^^^^^^^^^^^^^^^^^^^^^^
  File "C:\Users\akhil\AppData\Local\Programs\Python\Python312\Lib\site-packages\typer\main.py", line 698, in wrapper
    return callback(**use_params)
           ^^^^^^^^^^^^^^^^^^^^^^
  File "C:\Users\akhil\AppData\Local\Programs\Python\Python312\Lib\site-packages\spacy\cli\download.py", line 43, in download_cli
    download(model, direct, sdist, *ctx.args)
  File "C:\Users\akhil\AppData\Local\Programs\Python\Python312\Lib\site-packages\spacy\cli\download.py", line 77, in download
    compatibility = get_compatibility()
                    ^^^^^^^^^^^^^^^^^^^
  File "C:\Users\akhil\AppData\Local\Programs\Python\Python312\Lib\site-packages\spacy\cli\download.py", line 122, in get_compatibility
    r = requests.get(about.__compatibility__)
        ^^^^^^^^^^^^^^^^^^^^^^^^^^^^^^^^^^^^^
  File "C:\Users\akhil\AppData\Local\Programs\Python\Python312\Lib\site-packages\requests\api.py", line 73, in get
    return request("get", url, params=params, **kwargs)
           ^^^^^^^^^^^^^^^^^^^^^^^^^^^^^^^^^^^^^^^^^^^^
  File "C:\Users\akhil\AppData\Local\Programs\Python\Python312\Lib\site-packages\requests\api.py", line 59, in request
    return session.request(method=method, url=url, **kwargs)
           ^^^^^^^^^^^^^^^^^^^^^^^^^^^^^^^^^^^^^^^^^^^^^^^^^
  File "C:\Users\akhil\AppData\Local\Programs\Python\Python312\Lib\site-packages\requests\sessions.py", line 589, in request
    resp = self.send(prep, **send_kwargs)
           ^^^^^^^^^^^^^^^^^^^^^^^^^^^^^^
  File "C:\Users\akhil\AppData\Local\Programs\Python\Python312\Lib\site-packages\requests\sessions.py", line 703, in send
    r = adapter.send(request, **kwargs)
        ^^^^^^^^^^^^^^^^^^^^^^^^^^^^^^^
  File "C:\Users\akhil\AppData\Local\Programs\Python\Python312\Lib\site-packages\requests\adapters.py", line 639, in send
    self.cert_verify(conn, request.url, verify, cert)
  File "C:\Users\akhil\AppData\Local\Programs\Python\Python312\Lib\site-packages\requests\adapters.py", line 328, in cert_verify
    raise OSError(
OSError: Could not find a suitable TLS CA certificate bundle, invalid path: C:\Program Files\PostgreSQL\17\ssl\certs\ca-bundle.crt

2025-04-25 23:37:55,974 - __main__ - INFO - Dependencies installed successfully
2025-04-25 23:37:55,974 - __main__ - INFO - Installation completed successfully
2025-04-25 23:40:45,335 - __main__ - INFO - Starting installation...
2025-04-25 23:40:45,335 - __main__ - INFO - Creating directories...
2025-04-25 23:40:45,335 - __main__ - INFO - Created directory: models/nlp
2025-04-25 23:40:45,336 - __main__ - INFO - Created directory: models/wake_word
2025-04-25 23:40:45,336 - __main__ - INFO - Created directory: data/voice
2025-04-25 23:40:45,336 - __main__ - INFO - Created directory: data/conversation
2025-04-25 23:40:45,336 - __main__ - INFO - Created directory: logs
2025-04-25 23:40:45,336 - __main__ - INFO - Directories created successfully
2025-04-25 23:40:45,337 - __main__ - INFO - Installing dependencies...
2025-04-25 23:40:45,337 - __main__ - INFO - Checking Python version...
2025-04-25 23:40:45,337 - __main__ - WARNING - Python version 3.12 may have compatibility issues with some packages.
2025-04-25 23:40:45,337 - __main__ - WARNING - Consider using Python 3.8-3.11 for better compatibility.
2025-04-25 23:40:45,338 - __main__ - INFO - Python version 3.12 is compatible.
2025-04-25 23:40:45,338 - __main__ - INFO - Running: Upgrading pip
2025-04-25 23:40:48,539 - __main__ - ERROR - Command failed: Upgrading pip
2025-04-25 23:40:48,539 - __main__ - ERROR - Error: WARNING: Ignoring invalid distribution ~otebook (C:\Users\akhil\AppData\Local\Programs\Python\Python312\Lib\site-packages)
ERROR: Could not install packages due to an OSError: Could not find a suitable TLS CA certificate bundle, invalid path: C:\Program Files\PostgreSQL\17\ssl\certs\ca-bundle.crt


2025-04-25 23:40:48,540 - __main__ - INFO - Running: Installing setuptools and wheel
2025-04-25 23:40:51,682 - __main__ - ERROR - Command failed: Installing setuptools and wheel
2025-04-25 23:40:51,683 - __main__ - ERROR - Error: WARNING: Ignoring invalid distribution ~otebook (C:\Users\akhil\AppData\Local\Programs\Python\Python312\Lib\site-packages)
ERROR: Could not install packages due to an OSError: Could not find a suitable TLS CA certificate bundle, invalid path: C:\Program Files\PostgreSQL\17\ssl\certs\ca-bundle.crt


2025-04-25 23:40:51,684 - __main__ - INFO - Running: Installing numpy>=1.21.0
2025-04-25 23:40:56,360 - __main__ - INFO - Command completed successfully: Installing numpy>=1.21.0
2025-04-25 23:40:56,360 - __main__ - INFO - Running: Installing pandas>=2.0.0
2025-04-25 23:41:00,949 - __main__ - INFO - Command completed successfully: Installing pandas>=2.0.0
2025-04-25 23:41:00,950 - __main__ - INFO - Running: Installing scipy>=1.10.0
2025-04-25 23:41:05,659 - __main__ - INFO - Command completed successfully: Installing scipy>=1.10.0
2025-04-25 23:41:05,660 - __main__ - INFO - Running: Installing PyYAML>=6.0
2025-04-25 23:41:09,902 - __main__ - INFO - Command completed successfully: Installing PyYAML>=6.0
2025-04-25 23:41:09,903 - __main__ - INFO - Running: Installing python-dotenv>=1.0.0
2025-04-25 23:41:14,578 - __main__ - INFO - Command completed successfully: Installing python-dotenv>=1.0.0
2025-04-25 23:41:14,578 - __main__ - INFO - Running: Installing aiohttp>=3.8.0
2025-04-25 23:41:18,874 - __main__ - INFO - Command completed successfully: Installing aiohttp>=3.8.0
2025-04-25 23:41:18,874 - __main__ - INFO - Running: Installing asyncio>=3.4.3
2025-04-25 23:41:23,089 - __main__ - INFO - Command completed successfully: Installing asyncio>=3.4.3
2025-04-25 23:41:23,089 - __main__ - INFO - Running: Installing typing-extensions>=4.5.0
2025-04-25 23:41:27,769 - __main__ - INFO - Command completed successfully: Installing typing-extensions>=4.5.0
2025-04-25 23:41:27,770 - __main__ - INFO - Running: Installing sounddevice>=0.4.4
2025-04-25 23:41:31,971 - __main__ - INFO - Command completed successfully: Installing sounddevice>=0.4.4
2025-04-25 23:41:31,972 - __main__ - INFO - Running: Installing soundfile>=0.10.3
2025-04-25 23:41:36,231 - __main__ - INFO - Command completed successfully: Installing soundfile>=0.10.3
2025-04-25 23:41:36,231 - __main__ - INFO - Running: Installing pyttsx3>=2.90
2025-04-25 23:41:40,791 - __main__ - INFO - Command completed successfully: Installing pyttsx3>=2.90
2025-04-25 23:41:40,792 - __main__ - INFO - Running: Installing SpeechRecognition>=3.8.1
2025-04-25 23:41:45,016 - __main__ - INFO - Command completed successfully: Installing SpeechRecognition>=3.8.1
2025-04-25 23:41:45,016 - __main__ - INFO - Running: Installing pyaudio>=0.2.11
2025-04-25 23:41:49,207 - __main__ - INFO - Command completed successfully: Installing pyaudio>=0.2.11
2025-04-25 23:41:49,208 - __main__ - INFO - Running: Installing spaCy model
2025-04-25 23:41:54,992 - __main__ - ERROR - Command failed: Installing spaCy model
2025-04-25 23:41:54,992 - __main__ - ERROR - Error: Traceback (most recent call last):
  File "<frozen runpy>", line 198, in _run_module_as_main
  File "<frozen runpy>", line 88, in _run_code
  File "C:\Users\akhil\AppData\Local\Programs\Python\Python312\Lib\site-packages\spacy\__main__.py", line 4, in <module>
    setup_cli()
  File "C:\Users\akhil\AppData\Local\Programs\Python\Python312\Lib\site-packages\spacy\cli\_util.py", line 87, in setup_cli
    command(prog_name=COMMAND)
  File "C:\Users\akhil\AppData\Local\Programs\Python\Python312\Lib\site-packages\click\core.py", line 1161, in __call__
    return self.main(*args, **kwargs)
           ^^^^^^^^^^^^^^^^^^^^^^^^^^
  File "C:\Users\akhil\AppData\Local\Programs\Python\Python312\Lib\site-packages\typer\core.py", line 783, in main
    return _main(
           ^^^^^^
  File "C:\Users\akhil\AppData\Local\Programs\Python\Python312\Lib\site-packages\typer\core.py", line 225, in _main
    rv = self.invoke(ctx)
         ^^^^^^^^^^^^^^^^
  File "C:\Users\akhil\AppData\Local\Programs\Python\Python312\Lib\site-packages\click\core.py", line 1697, in invoke
    return _process_result(sub_ctx.command.invoke(sub_ctx))
                           ^^^^^^^^^^^^^^^^^^^^^^^^^^^^^^^
  File "C:\Users\akhil\AppData\Local\Programs\Python\Python312\Lib\site-packages\click\core.py", line 1443, in invoke
    return ctx.invoke(self.callback, **ctx.params)
           ^^^^^^^^^^^^^^^^^^^^^^^^^^^^^^^^^^^^^^^
  File "C:\Users\akhil\AppData\Local\Programs\Python\Python312\Lib\site-packages\click\core.py", line 788, in invoke
    return __callback(*args, **kwargs)
           ^^^^^^^^^^^^^^^^^^^^^^^^^^^
  File "C:\Users\akhil\AppData\Local\Programs\Python\Python312\Lib\site-packages\typer\main.py", line 683, in wrapper
    return callback(**use_params)  # type: ignore
           ^^^^^^^^^^^^^^^^^^^^^^
  File "C:\Users\akhil\AppData\Local\Programs\Python\Python312\Lib\site-packages\spacy\cli\download.py", line 43, in download_cli
    download(model, direct, sdist, *ctx.args)
  File "C:\Users\akhil\AppData\Local\Programs\Python\Python312\Lib\site-packages\spacy\cli\download.py", line 77, in download
    compatibility = get_compatibility()
                    ^^^^^^^^^^^^^^^^^^^
  File "C:\Users\akhil\AppData\Local\Programs\Python\Python312\Lib\site-packages\spacy\cli\download.py", line 122, in get_compatibility
    r = requests.get(about.__compatibility__)
        ^^^^^^^^^^^^^^^^^^^^^^^^^^^^^^^^^^^^^
  File "C:\Users\akhil\AppData\Local\Programs\Python\Python312\Lib\site-packages\requests\api.py", line 73, in get
    return request("get", url, params=params, **kwargs)
           ^^^^^^^^^^^^^^^^^^^^^^^^^^^^^^^^^^^^^^^^^^^^
  File "C:\Users\akhil\AppData\Local\Programs\Python\Python312\Lib\site-packages\requests\api.py", line 59, in request
    return session.request(method=method, url=url, **kwargs)
           ^^^^^^^^^^^^^^^^^^^^^^^^^^^^^^^^^^^^^^^^^^^^^^^^^
  File "C:\Users\akhil\AppData\Local\Programs\Python\Python312\Lib\site-packages\requests\sessions.py", line 589, in request
    resp = self.send(prep, **send_kwargs)
           ^^^^^^^^^^^^^^^^^^^^^^^^^^^^^^
  File "C:\Users\akhil\AppData\Local\Programs\Python\Python312\Lib\site-packages\requests\sessions.py", line 703, in send
    r = adapter.send(request, **kwargs)
        ^^^^^^^^^^^^^^^^^^^^^^^^^^^^^^^
  File "C:\Users\akhil\AppData\Local\Programs\Python\Python312\Lib\site-packages\requests\adapters.py", line 639, in send
    self.cert_verify(conn, request.url, verify, cert)
  File "C:\Users\akhil\AppData\Local\Programs\Python\Python312\Lib\site-packages\requests\adapters.py", line 328, in cert_verify
    raise OSError(
OSError: Could not find a suitable TLS CA certificate bundle, invalid path: C:\Program Files\PostgreSQL\17\ssl\certs\ca-bundle.crt

2025-04-25 23:41:55,002 - __main__ - INFO - Dependencies installed successfully
2025-04-25 23:41:55,002 - __main__ - INFO - Installation completed successfully
2025-04-25 23:42:06,719 - __main__ - INFO - Starting installation...
2025-04-25 23:42:06,719 - __main__ - INFO - Creating directories...
2025-04-25 23:42:06,719 - __main__ - INFO - Created directory: models/nlp
2025-04-25 23:42:06,720 - __main__ - INFO - Created directory: models/wake_word
2025-04-25 23:42:06,720 - __main__ - INFO - Created directory: data/voice
2025-04-25 23:42:06,720 - __main__ - INFO - Created directory: data/conversation
2025-04-25 23:42:06,720 - __main__ - INFO - Created directory: logs
2025-04-25 23:42:06,720 - __main__ - INFO - Directories created successfully
2025-04-25 23:42:06,721 - __main__ - INFO - Installing dependencies...
2025-04-25 23:42:06,721 - __main__ - INFO - Checking Python version...
2025-04-25 23:42:06,721 - __main__ - WARNING - Python version 3.12 may have compatibility issues with some packages.
2025-04-25 23:42:06,721 - __main__ - WARNING - Consider using Python 3.8-3.11 for better compatibility.
2025-04-25 23:42:06,721 - __main__ - INFO - Python version 3.12 is compatible.
2025-04-25 23:42:06,721 - __main__ - INFO - Running: Upgrading pip
2025-04-25 23:42:09,733 - __main__ - ERROR - Command failed: Upgrading pip
2025-04-25 23:42:09,733 - __main__ - ERROR - Error: WARNING: Ignoring invalid distribution ~otebook (C:\Users\akhil\AppData\Local\Programs\Python\Python312\Lib\site-packages)
ERROR: Could not install packages due to an OSError: Could not find a suitable TLS CA certificate bundle, invalid path: C:\Program Files\PostgreSQL\17\ssl\certs\ca-bundle.crt


2025-04-25 23:42:09,734 - __main__ - INFO - Running: Installing setuptools and wheel
2025-04-25 23:42:12,841 - __main__ - ERROR - Command failed: Installing setuptools and wheel
2025-04-25 23:42:12,841 - __main__ - ERROR - Error: WARNING: Ignoring invalid distribution ~otebook (C:\Users\akhil\AppData\Local\Programs\Python\Python312\Lib\site-packages)
ERROR: Could not install packages due to an OSError: Could not find a suitable TLS CA certificate bundle, invalid path: C:\Program Files\PostgreSQL\17\ssl\certs\ca-bundle.crt


2025-04-25 23:42:12,842 - __main__ - INFO - Running: Installing numpy>=1.21.0
2025-04-25 23:42:17,689 - __main__ - INFO - Command completed successfully: Installing numpy>=1.21.0
2025-04-25 23:42:17,689 - __main__ - INFO - Running: Installing pandas>=2.0.0
2025-04-25 23:42:22,004 - __main__ - INFO - Command completed successfully: Installing pandas>=2.0.0
2025-04-25 23:42:22,005 - __main__ - INFO - Running: Installing scipy>=1.10.0
2025-04-25 23:42:26,520 - __main__ - INFO - Command completed successfully: Installing scipy>=1.10.0
2025-04-25 23:42:26,521 - __main__ - INFO - Running: Installing PyYAML>=6.0
2025-04-25 23:42:31,469 - __main__ - INFO - Command completed successfully: Installing PyYAML>=6.0
2025-04-25 23:42:31,469 - __main__ - INFO - Running: Installing python-dotenv>=1.0.0
2025-04-25 23:42:35,950 - __main__ - INFO - Command completed successfully: Installing python-dotenv>=1.0.0
2025-04-25 23:42:35,951 - __main__ - INFO - Running: Installing aiohttp>=3.8.0
2025-04-25 23:42:40,416 - __main__ - INFO - Command completed successfully: Installing aiohttp>=3.8.0
2025-04-25 23:42:40,416 - __main__ - INFO - Running: Installing asyncio>=3.4.3
2025-04-25 23:42:45,206 - __main__ - INFO - Command completed successfully: Installing asyncio>=3.4.3
2025-04-25 23:42:45,207 - __main__ - INFO - Running: Installing typing-extensions>=4.5.0
2025-04-25 23:42:49,717 - __main__ - INFO - Command completed successfully: Installing typing-extensions>=4.5.0
2025-04-25 23:42:49,717 - __main__ - INFO - Running: Installing sounddevice>=0.4.4
2025-04-25 23:42:53,932 - __main__ - INFO - Command completed successfully: Installing sounddevice>=0.4.4
2025-04-25 23:42:53,932 - __main__ - INFO - Running: Installing soundfile>=0.10.3
2025-04-25 23:42:58,559 - __main__ - INFO - Command completed successfully: Installing soundfile>=0.10.3
2025-04-25 23:42:58,559 - __main__ - INFO - Running: Installing pyttsx3>=2.90
2025-04-25 23:43:03,496 - __main__ - INFO - Command completed successfully: Installing pyttsx3>=2.90
2025-04-25 23:43:03,497 - __main__ - INFO - Running: Installing SpeechRecognition>=3.8.1
2025-04-25 23:43:09,747 - __main__ - INFO - Command completed successfully: Installing SpeechRecognition>=3.8.1
2025-04-25 23:43:09,748 - __main__ - INFO - Running: Installing pyaudio>=0.2.11
2025-04-25 23:43:14,436 - __main__ - INFO - Command completed successfully: Installing pyaudio>=0.2.11
2025-04-25 23:43:14,437 - __main__ - INFO - Running: Installing spaCy model
2025-04-25 23:43:21,453 - __main__ - ERROR - Command failed: Installing spaCy model
2025-04-25 23:43:21,453 - __main__ - ERROR - Error: Traceback (most recent call last):
  File "<frozen runpy>", line 198, in _run_module_as_main
  File "<frozen runpy>", line 88, in _run_code
  File "C:\Users\akhil\AppData\Local\Programs\Python\Python312\Lib\site-packages\spacy\__main__.py", line 4, in <module>
    setup_cli()
  File "C:\Users\akhil\AppData\Local\Programs\Python\Python312\Lib\site-packages\spacy\cli\_util.py", line 87, in setup_cli
    command(prog_name=COMMAND)
  File "C:\Users\akhil\AppData\Local\Programs\Python\Python312\Lib\site-packages\click\core.py", line 1161, in __call__
    return self.main(*args, **kwargs)
           ^^^^^^^^^^^^^^^^^^^^^^^^^^
  File "C:\Users\akhil\AppData\Local\Programs\Python\Python312\Lib\site-packages\typer\core.py", line 783, in main
    return _main(
           ^^^^^^
  File "C:\Users\akhil\AppData\Local\Programs\Python\Python312\Lib\site-packages\typer\core.py", line 225, in _main
    rv = self.invoke(ctx)
         ^^^^^^^^^^^^^^^^
  File "C:\Users\akhil\AppData\Local\Programs\Python\Python312\Lib\site-packages\click\core.py", line 1697, in invoke
    return _process_result(sub_ctx.command.invoke(sub_ctx))
                           ^^^^^^^^^^^^^^^^^^^^^^^^^^^^^^^
  File "C:\Users\akhil\AppData\Local\Programs\Python\Python312\Lib\site-packages\click\core.py", line 1443, in invoke
    return ctx.invoke(self.callback, **ctx.params)
           ^^^^^^^^^^^^^^^^^^^^^^^^^^^^^^^^^^^^^^^
  File "C:\Users\akhil\AppData\Local\Programs\Python\Python312\Lib\site-packages\click\core.py", line 788, in invoke
    return __callback(*args, **kwargs)
           ^^^^^^^^^^^^^^^^^^^^^^^^^^^
  File "C:\Users\akhil\AppData\Local\Programs\Python\Python312\Lib\site-packages\typer\main.py", line 683, in wrapper
    return callback(**use_params)  # type: ignore
           ^^^^^^^^^^^^^^^^^^^^^^
  File "C:\Users\akhil\AppData\Local\Programs\Python\Python312\Lib\site-packages\spacy\cli\download.py", line 43, in download_cli
    download(model, direct, sdist, *ctx.args)
  File "C:\Users\akhil\AppData\Local\Programs\Python\Python312\Lib\site-packages\spacy\cli\download.py", line 77, in download
    compatibility = get_compatibility()
                    ^^^^^^^^^^^^^^^^^^^
  File "C:\Users\akhil\AppData\Local\Programs\Python\Python312\Lib\site-packages\spacy\cli\download.py", line 122, in get_compatibility
    r = requests.get(about.__compatibility__)
        ^^^^^^^^^^^^^^^^^^^^^^^^^^^^^^^^^^^^^
  File "C:\Users\akhil\AppData\Local\Programs\Python\Python312\Lib\site-packages\requests\api.py", line 73, in get
    return request("get", url, params=params, **kwargs)
           ^^^^^^^^^^^^^^^^^^^^^^^^^^^^^^^^^^^^^^^^^^^^
  File "C:\Users\akhil\AppData\Local\Programs\Python\Python312\Lib\site-packages\requests\api.py", line 59, in request
    return session.request(method=method, url=url, **kwargs)
           ^^^^^^^^^^^^^^^^^^^^^^^^^^^^^^^^^^^^^^^^^^^^^^^^^
  File "C:\Users\akhil\AppData\Local\Programs\Python\Python312\Lib\site-packages\requests\sessions.py", line 589, in request
    resp = self.send(prep, **send_kwargs)
           ^^^^^^^^^^^^^^^^^^^^^^^^^^^^^^
  File "C:\Users\akhil\AppData\Local\Programs\Python\Python312\Lib\site-packages\requests\sessions.py", line 703, in send
    r = adapter.send(request, **kwargs)
        ^^^^^^^^^^^^^^^^^^^^^^^^^^^^^^^
  File "C:\Users\akhil\AppData\Local\Programs\Python\Python312\Lib\site-packages\requests\adapters.py", line 639, in send
    self.cert_verify(conn, request.url, verify, cert)
  File "C:\Users\akhil\AppData\Local\Programs\Python\Python312\Lib\site-packages\requests\adapters.py", line 328, in cert_verify
    raise OSError(
OSError: Could not find a suitable TLS CA certificate bundle, invalid path: C:\Program Files\PostgreSQL\17\ssl\certs\ca-bundle.crt

2025-04-25 23:43:21,463 - __main__ - INFO - Dependencies installed successfully
2025-04-25 23:43:21,463 - __main__ - INFO - Installation completed successfully
